Workbook

Sheet Odogaon
A1: descriptio | B1: FID | C1: Longitude | D1: Latitude | E1: Depth_m | F1: Area_m2 | G1: Kharif_str | H1: Rabi_strg | I1: Summer_str | J1: Total_stor
A2: Lakes/Ponds | B2: 6 | C2: 20.0315 | D2: 85.101 | E2: 2 | F2: 101.13 | G2: 202.26 | H2: 101.13 | I2: 50.57 | J2: 353.96
A3: Lakes/Ponds | B3: 275 | C3: 20.0329 | D3: 84.9776 | E3: 2 | F3: 140.15 | G3: 280.3 | H3: 140.15 | I3: 70.08 | J3: 490.53
A4: Lakes/Ponds | B4: 0 | C4: 20.0375 | D4: 85.1137 | E4: 2 | F4: 224.24 | G4: 448.48 | H4: 224.24 | I4: 112.12 | J4: 784.84
A5: Lakes/Ponds | B5: 120 | C5: 20.0332 | D5: 85.0265 | E5: 2 | F5: 233.98 | G5: 467.96 | H5: 233.98 | I5: 116.99 | J5: 818.93
A6: Lakes/Ponds | B6: 1 | C6: 20.0123 | D6: 85.0825 | E6: 2 | F6: 240.41 | G6: 480.82 | H6: 240.41 | I6: 120.21 | J6: 841.44
A7: Lakes/Ponds | B7: 4 | C7: 20.0385 | D7: 85.1135 | E7: 2 | F7: 245.48 | G7: 490.96 | H7: 245.48 | I7: 122.74 | J7: 859.18
A8: Lakes/Ponds | B8: 242 | C8: 20.0178 | D8: 85.0856 | E8: 2 | F8: 263.54 | G8: 527.08 | H8: 263.54 | I8: 131.77 | J8: 922.39
A9: Lakes/Ponds | B9: 279 | C9: 20.0511 | D9: 85.146 | E9: 2 | F9: 263.58 | G9: 527.16 | H9: 263.58 | I9: 131.79 | J9: 922.53
A10: Lakes/Ponds | B10: 240 | C10: 20.039 | D10: 85.1128 | E10: 2 | F10: 283.06 | G10: 566.12 | H10: 283.06 | I10: 141.53 | J10: 990.71
A11: Lakes/Ponds | B11: 5 | C11: 20.0391 | D11: 85.1135 | E11: 2 | F11: 295.2 | G11: 590.4 | H11: 295.2 | I11: 147.6 | J11: 1033.2
A12: Lakes/Ponds | B12: 198 | C12: 20.0407 | D12: 85.1185 | E12: 2 | F12: 305.23 | G12: 610.46 | H12: 305.23 | I12: 152.62 | J12: 1068.31
A13: Lakes/Ponds | B13: 7 | C13: 20.0379 | D13: 84.967 | E13: 2 | F13: 325.86 | G13: 651.72 | H13: 325.86 | I13: 162.93 | J13: 1140.51
A14: Lakes/Ponds | B14: 195 | C14: 20.041 | D14: 85.1135 | E14: 2 | F14: 333.29 | G14: 666.58 | H14: 333.29 | I14: 166.65 | J14: 1166.52 | K14: `
A15: Lakes/Ponds | B15: 40 | C15: 20.0318 | D15: 84.9767 | E15: 2 | F15: 343.77 | G15: 687.54 | H15: 343.77 | I15: 171.89 | J15: 1203.2
A16: Lakes/Ponds | B16: 196 | C16: 20.0409 | D16: 85.1154 | E16: 2 | F16: 372.39 | G16: 744.78 | H16: 372.39 | I16: 186.2 | J16: 1303.37
A17: Lakes/Ponds | B17: 79 | C17: 20.0214 | D17: 85.0097 | E17: 2.5 | F17: 306.53 | G17: 766.33 | H17: 383.16 | I17: 191.58 | J17: 1341.07
A18: Lakes/Ponds | B18: 145 | C18: 20.045 | D18: 85.0351 | E18: 2 | F18: 384.65 | G18: 769.3 | H18: 384.65 | I18: 192.33 | J18: 1346.28
A19: Lakes/Ponds | B19: 39 | C19: 20.0396 | D19: 84.9752 | E19: 2 | F19: 385.63 | G19: 771.26 | H19: 385.63 | I19: 192.82 | J19: 1349.71
A20: Lakes/Ponds | B20: 2 | C20: 20.0379 | D20: 85.1134 | E20: 2 | F20: 402.31 | G20: 804.62 | H20: 402.31 | I20: 201.16 | J20: 1408.09
A21: Lakes/Ponds | B21: 280 | C21: 20.0513 | D21: 85.1463 | E21: 2 | F21: 407.06 | G21: 814.12 | H21: 407.06 | I21: 203.53 | J21: 1424.71
A22: Lakes/Ponds | B22: 172 | C22: 20.0297 | D22: 85.049 | E22: 2 | F22: 412.47 | G22: 824.94 | H22: 412.47 | I22: 206.24 | J22: 1443.65
A23: Lakes/Ponds | B23: 15 | C23: 20.0237 | D23: 84.9869 | E23: 2 | F23: 425.84 | G23: 851.68 | H23: 425.84 | I23: 212.92 | J23: 1490.44
A24: Lakes/Ponds | B24: 44 | C24: 20.0171 | D24: 84.9835 | E24: 2 | F24: 426.4 | G24: 852.8 | H24: 426.4 | I24: 213.2 | J24: 1492.4
A25: Lakes/Ponds | B25: 197 | C25: 20.0396 | D25: 85.1156 | E25: 2 | F25: 426.42 | G25: 852.84 | H25: 426.42 | I25: 213.21 | J25: 1492.47
A26: Lakes/Ponds | B26: 232 | C26: 20.0325 | D26: 85.1022 | E26: 2 | F26: 427.99 | G26: 855.98 | H26: 427.99 | I26: 214 | J26: 1497.97
... A285: Lakes/Ponds | B285: 92 | C285: 20.0115 | D285: 85.0233 | E285: 4 | F285: 77727.92 | G285: 310911.68 | H285: 155455.84 | I285: 77727.92 | J285: 544095.44
A286: Total | E286: =AVERAGE(E2:E285) -> 2.9545775 | F286: =SUM(F2:F285) -> 1304509.8 | G286: =SUM(G2:G285) -> 4457235.8 | H286: =SUM(H2:H285) -> 2228618.1 | I286: =SUM(I2:I285) -> 1114309.1 | J286: =SUM(J2:J285) -> 7800163

Sheet Odogaon_22
A1: FID | B1: Latitude | C1: Longitude | D1: Category | E1: Name | F1: Depth_m | G1: Area_m2 | H1: MWS Name | I1: Depth_m (after deducting safe factor) | J1: Storage (m3)
J2: Jan | K2: Feb | L2: Mar | M2: Apr | N2: May | O2: Jun | P2: Jul | Q2: Aug | R2: Sep | S2: Oct | T2: Nov | U2: Dec | V2: Max
A3: 0 | B3: 20.0375 | C3: 85.1137 | D3: Lakes/Ponds | E3: NA | F3: 2 | G3: 224.24 | H3: Sikharpur | I3: =F3-$AC$20 -> 1.75 | J3: =IF($I3-Z$24<0, 0, ($I3-Z$24)*$G3) -> 309.67544 | K3: =IF($I3-AA$24<0, 0, ($I3-AA$24)*$G3) -> 271.46494 | L3: =IF($I3-AB$24<0, 0, ($I3-AB$24)*$G3) -> 227.06542 | M3: =IF($I3-AC$24<0, 0, ($I3-AC$24)*$G3) -> 181.11865 | N3: =IF($I3-AD$24<0, 0, ($I3-AD$24)*$G3) -> 127.43559 | O3: =IF($I3-AE$24<0, 0, ($I3-AE$24)*$G3) -> 127.43559 | P3: =IF($I3-AF$24<0, 0, ($I3-AF$24)*$G3) -> 392.42 | Q3: =IF($I3-AG$24<0, 0, ($I3-AG$24)*$G3) -> 392.42 | ... U3: =IF($I3-AK$24<0, 0, ($I3-AK$24)*$G3) -> 338.19877 | V3: =MAX(J3:U3) -> 392.42 | Y3: Month | Z3: Season | AA3: Evaporation (mm/day) | AB3: Deep percolation (mm/day) | AC3: Total (mm/day) | AD3: Total (mm/month) | AE3: Total Depth (m/month) | AF3: Total cummulative Depth (m/month)
A4: 1 | B4: 20.0123 | C4: 85.0825 | D4: Lakes/Ponds | E4: NA | F4: 2 | G4: 240.41 | H4: Dhusuma | I4: =F4-$AC$20 -> 1.75 | J4: =IF($I4-Z$24<0, 0, ($I4-Z$24)*$G4) -> 332.00621 | K4: =IF($I4-AA$24<0, 0, ($I4-AA$24)*$G4) -> 291.04035 | L4: =IF($I4-AB$24<0, 0, ($I4-AB$24)*$G4) -> 243.43917 | M4: =IF($I4-AC$24<0, 0, ($I4-AC$24)*$G4) -> 194.17916 | N4: =IF($I4-AD$24<0, 0, ($I4-AD$24)*$G4) -> 136.625 | O4: =IF($I4-AE$24<0, 0, ($I4-AE$24)*$G4) -> 136.625 | P4: =IF($I4-AF$24<0, 0, ($I4-AF$24)*$G4) -> 420.7175 | Q4: =IF($I4-AG$24<0, 0, ($I4-AG$24)*$G4) -> 420.7175 | ... U4: =IF($I4-AK$24<0, 0, ($I4-AK$24)*$G4) -> 362.58636 | V4: =MAX(J4:U4) -> 420.7175 | Y4: Jan | Z4: Rabi | AA4: 2.24 | AB4: 2 | AC4: =AA4+AB4 -> 4.24 | AD4: =AC4*30 -> 127.2 | AE4: =AD4/1000 -> 0.1272 | AF4: =AF15+AE4 -> 0.369
A5: 2 | B5: 20.0379 | C5: 85.1134 | D5: Lakes/Ponds | E5: NA | F5: 2 | G5: 402.31 | H5: Sikharpur | I5: =F5-$AC$20 -> 1.75 | J5: =IF($I5-Z$24<0, 0, ($I5-Z$24)*$G5) -> 555.59011 | K5: =IF($I5-AA$24<0, 0, ($I5-AA$24)*$G5) -> 487.03649 | L5: =IF($I5-AB$24<0, 0, ($I5-AB$24)*$G5) -> 407.37911 | M5: =IF($I5-AC$24<0, 0, ($I5-AC$24)*$G5) -> 324.94579 | N5: =IF($I5-AD$24<0, 0, ($I5-AD$24)*$G5) -> 228.63277 | O5: =IF($I5-AE$24<0, 0, ($I5-AE$24)*$G5) -> 228.63277 | P5: =IF($I5-AF$24<0, 0, ($I5-AF$24)*$G5) -> 704.0425 | Q5: =IF($I5-AG$24<0, 0, ($I5-AG$24)*$G5) -> 704.0425 | ... U5: =IF($I5-AK$24<0, 0, ($I5-AK$24)*$G5) -> 606.76394 | V5: =MAX(J5:U5) -> 704.0425 | Y5: Feb | Z5: Rabi | AA5: 3.68 | AB5: 2 | AC5: =AA5+AB5 -> 5.68 | AD5: =AC5*30 -> 170.4 | AE5: =AD5/1000 -> 0.1704 | AF5: =AF4+AE5 -> 0.5394
A6: 3 | B6: 20.0108 | C6: 85.0825 | D6: Lakes/Ponds | E6: NA | F6: 3 | G6: 2124.01 | H6: Dhusuma | I6: =F6-$AC$20 -> 2.75 | J6: =IF($I6-Z$24<0, 0, ($I6-Z$24)*$G6) -> 5057.2678 | K6: =IF($I6-AA$24<0, 0, ($I6-AA$24)*$G6) -> 4695.3365 | L6: =IF($I6-AB$24<0, 0, ($I6-AB$24)*$G6) -> 4274.7825 | M6: =IF($I6-AC$24<0, 0, ($I6-AC$24)*$G6) -> 3839.5729 | N6: =IF($I6-AD$24<0, 0, ($I6-AD$24)*$G6) -> 3331.0849 | O6: =IF($I6-AE$24<0, 0, ($I6-AE$24)*$G6) -> 3331.0849 | P6: =IF($I6-AF$24<0, 0, ($I6-AF$24)*$G6) -> 5841.0275 | Q6: =IF($I6-AG$24<0, 0, ($I6-AG$24)*$G6) -> 5841.0275 | ... U6: =IF($I6-AK$24<0, 0, ($I6-AK$24)*$G6) -> 5327.4419 | V6: =MAX(J6:U6) -> 5841.0275 | Y6: Mar | Z6: Summer | AA6: 4.6 | AB6: 2 | AC6: =AA6+AB6 -> 6.6 | AD6: =AC6*30 -> 198 | AE6: =AD6/1000 -> 0.198 | AF6: =AF5+AE6 -> 0.7374
A7: 4 | B7: 20.0385 | C7: 85.1135 | D7: Lakes/Ponds | E7: NA | F7: 2 | G7: 245.48 | H7: Sikharpur | I7: =F7-$AC$20 -> 1.75 | J7: =IF($I7-Z$24<0, 0, ($I7-Z$24)*$G7) -> 339.00788 | K7: =IF($I7-AA$24<0, 0, ($I7-AA$24)*$G7) -> 297.17809 | L7: =IF($I7-AB$24<0, 0, ($I7-AB$24)*$G7) -> 248.57305 | M7: =IF($I7-AC$24<0, 0, ($I7-AC$24)*$G7) -> 198.2742 | N7: =IF($I7-AD$24<0, 0, ($I7-AD$24)*$G7) -> 139.50628 | O7: =IF($I7-AE$24<0, 0, ($I7-AE$24)*$G7) -> 139.50628 | P7: =IF($I7-AF$24<0, 0, ($I7-AF$24)*$G7) -> 429.59 | Q7: =IF($I7-AG$24<0, 0, ($I7-AG$24)*$G7) -> 429.59 | ... U7: =IF($I7-AK$24<0, 0, ($I7-AK$24)*$G7) -> 370.23294 | V7: =MAX(J7:U7) -> 429.59 | Y7: Apr | Z7: Summer | AA7: 4.83 | AB7: 2 | AC7: =AA7+AB7 -> 6.83 | AD7: =AC7*30 -> 204.9 | AE7: =AD7/1000 -> 0.2049 | AF7: =AF6+AE7 -> 0.9423
A8: 5 | B8: 20.0391 | C8: 85.1135 | D8: Lakes/Ponds | E8: NA | F8: 2 | G8: 295.2 | H8: Sikharpur | I8: =F8-$AC$20 -> 1.75 | J8: =IF($I8-Z$24<0, 0, ($I8-Z$24)*$G8) -> 407.6712 | K8: =IF($I8-AA$24<0, 0, ($I8-AA$24)*$G8) -> 357.36912 | L8: =IF($I8-AB$24<0, 0, ($I8-AB$24)*$G8) -> 298.91952 | M8: =IF($I8-AC$24<0, 0, ($I8-AC$24)*$G8) -> 238.43304 | N8: =IF($I8-AD$24<0, 0, ($I8-AD$24)*$G8) -> 167.76216 | O8: =IF($I8-AE$24<0, 0, ($I8-AE$24)*$G8) -> 167.76216 | P8: =IF($I8-AF$24<0, 0, ($I8-AF$24)*$G8) -> 516.6 | Q8: =IF($I8-AG$24<0, 0, ($I8-AG$24)*$G8) -> 516.6 | ... U8: =IF($I8-AK$24<0, 0, ($I8-AK$24)*$G8) -> 445.22064 | V8: =MAX(J8:U8) -> 516.6 | Y8: May | Z8: Summer | AA8: 5.98 | AB8: 2 | AC8: =AA8+AB8 -> 7.98 | AD8: =AC8*30 -> 239.4 | AE8: =AD8/1000 -> 0.2394 | AF8: =AF7+AE8 -> 1.1817
A9: 6 | B9: 20.0315 | C9: 85.101 | D9: Lakes/Ponds | E9: NA | F9: 2 | G9: 101.13 | H9: Sikharpur | I9: =F9-$AC$20 -> 1.75 | J9: =IF($I9-Z$24<0, 0, ($I9-Z$24)*$G9) -> 139.66053 | K9: =IF($I9-AA$24<0, 0, ($I9-AA$24)*$G9) -> 122.42798 | L9: =IF($I9-AB$24<0, 0, ($I9-AB$24)*$G9) -> 102.40424 | M9: =IF($I9-AC$24<0, 0, ($I9-AC$24)*$G9) -> 81.682701 | N9: =IF($I9-AD$24<0, 0, ($I9-AD$24)*$G9) -> 57.472179 | O9: =IF($I9-AE$24<0, 0, ($I9-AE$24)*$G9) -> 57.472179 | P9: =IF($I9-AF$24<0, 0, ($I9-AF$24)*$G9) -> 176.9775 | Q9: =IF($I9-AG$24<0, 0, ($I9-AG$24)*$G9) -> 176.9775 | ... U9: =IF($I9-AK$24<0, 0, ($I9-AK$24)*$G9) -> 152.52427 | V9: =MAX(J9:U9) -> 176.9775 | Y9: Jun | Z9: Kharif | AA9: 3.98 | AB9: 2 | AC9: =AA9+AB9 -> 5.98 | AD9: =AC9*30 -> 179.4 | AE9: 0 | AF9: =AF8+AE9 -> 1.1817
A10: 7 | B10: 20.0379 | C10: 84.967 | D10: Lakes/Ponds | E10: NA | F10: 2 | G10: 325.86 | H10: Khubhiapalli | I10: =F10-$AC$20 -> 1.75 | J10: =IF($I10-Z$24<0, 0, ($I10-Z$24)*$G10) -> 450.01266 | K10: =IF($I10-AA$24<0, 0, ($I10-AA$24)*$G10) -> 394.48612 | L10: =IF($I10-AB$24<0, 0, ($I10-AB$24)*$G10) -> 329.96584 | M10: =IF($I10-AC$24<0, 0, ($I10-AC$24)*$G10) -> 263.19712 | N10: =IF($I10-AD$24<0, 0, ($I10-AD$24)*$G10) -> 185.18624 | O10: =IF($I10-AE$24<0, 0, ($I10-AE$24)*$G10) -> 185.18624 | P10: =IF($I10-AF$24<0, 0, ($I10-AF$24)*$G10) -> 570.255 | Q10: =IF($I10-AG$24<0, 0, ($I10-AG$24)*$G10) -> 570.255 | ... U10: =IF($I10-AK$24<0, 0, ($I10-AK$24)*$G10) -> 491.46205 | V10: =MAX(J10:U10) -> 570.255 | Y10: Jul | Z10: Kharif | AE10: 0 | AF10: 0
A11: 8 | B11: 20.0457 | C11: 85.0313 | D11: Lakes/Ponds | E11: NA | F11: 2 | G11: 830.15 | H11: Saradapur | I11: =F11-$AC$20 -> 1.75 | J11: =IF($I11-Z$24<0, 0, ($I11-Z$24)*$G11) -> 1146.4371 | K11: =IF($I11-AA$24<0, 0, ($I11-AA$24)*$G11) -> 1004.9796 | L11: =IF($I11-AB$24<0, 0, ($I11-AB$24)*$G11) -> 840.60989 | M11: =IF($I11-AC$24<0, 0, ($I11-AC$24)*$G11) -> 670.51216 | N11: =IF($I11-AD$24<0, 0, ($I11-AD$24)*$G11) -> 471.77425 | O11: =IF($I11-AE$24<0, 0, ($I11-AE$24)*$G11) -> 471.77425 | P11: =IF($I11-AF$24<0, 0, ($I11-AF$24)*$G11) -> 1452.7625 | Q11: =IF($I11-AG$24<0, 0, ($I11-AG$24)*$G11) -> 1452.7625 | ... U11: =IF($I11-AK$24<0, 0, ($I11-AK$24)*$G11) -> 1252.0322 | V11: =MAX(J11:U11) -> 1452.7625 | Y11: Aug | Z11: Kharif | AE11: 0 | AF11: 0
A12: 9 | B12: 20.0091 | C12: 85.0076 | D12: Lakes/Ponds | E12: NA | F12: 3 | G12: 857.31 | H12: Rabara | I12: =F12-$AC$20 -> 2.75 | J12: =IF($I12-Z$24<0, 0, ($I12-Z$24)*$G12) -> 2041.2551 | K12: =IF($I12-AA$24<0, 0, ($I12-AA$24)*$G12) -> 1895.1695 | L12: =IF($I12-AB$24<0, 0, ($I12-AB$24)*$G12) -> 1725.4221 | M12: =IF($I12-AC$24<0, 0, ($I12-AC$24)*$G12) -> 1549.7593 | N12: =IF($I12-AD$24<0, 0, ($I12-AD$24)*$G12) -> 1344.5193 | O12: =IF($I12-AE$24<0, 0, ($I12-AE$24)*$G12) -> 1344.5193 | P12: =IF($I12-AF$24<0, 0, ($I12-AF$24)*$G12) -> 2357.6025 | Q12: =IF($I12-AG$24<0, 0, ($I12-AG$24)*$G12) -> 2357.6025 | ... U12: =IF($I12-AK$24<0, 0, ($I12-AK$24)*$G12) -> 2150.3049 | V12: =MAX(J12:U12) -> 2357.6025 | Y12: Sep | Z12: Kharif | AE12: 0 | AF12: 0
A13: 10 | B13: 20.0341 | C13: 84.9667 | D13: Lakes/Ponds | E13: NA | F13: 3 | G13: 4729.47 | H13: Khubhiapalli | I13: =F13-$AC$20 -> 2.75 | J13: =IF($I13-Z$24<0, 0, ($I13-Z$24)*$G13) -> 11260.868 | K13: =IF($I13-AA$24<0, 0, ($I13-AA$24)*$G13) -> 10454.966 | L13: =IF($I13-AB$24<0, 0, ($I13-AB$24)*$G13) -> 9518.5313 | M13: =IF($I13-AC$24<0, 0, ($I13-AC$24)*$G13) -> 8549.4629 | N13: =IF($I13-AD$24<0, 0, ($I13-AD$24)*$G13) -> 7417.2278 | O13: =IF($I13-AE$24<0, 0, ($I13-AE$24)*$G13) -> 7417.2278 | P13: =IF($I13-AF$24<0, 0, ($I13-AF$24)*$G13) -> 13006.043 | Q13: =IF($I13-AG$24<0, 0, ($I13-AG$24)*$G13) -> 13006.043 | ... U13: =IF($I13-AK$24<0, 0, ($I13-AK$24)*$G13) -> 11862.457 | V13: =MAX(J13:U13) -> 13006.043 | Y13: Oct | Z13: Kharif | AE13: 0 | AF13: 0
A14: 11 | B14: 20.0168 | C14: 84.9898 | D14: Lakes/Ponds | E14: NA | F14: 3 | G14: 2642.2 | H14: Jaringi | I14: =F14-$AC$20 -> 2.75 | J14: =IF($I14-Z$24<0, 0, ($I14-Z$24)*$G14) -> 6291.0782 | K14: =IF($I14-AA$24<0, 0, ($I14-AA$24)*$G14) -> 5840.8473 | L14: =IF($I14-AB$24<0, 0, ($I14-AB$24)*$G14) -> 5317.6917 | M14: =IF($I14-AC$24<0, 0, ($I14-AC$24)*$G14) -> 4776.3049 | N14: =IF($I14-AD$24<0, 0, ($I14-AD$24)*$G14) -> 4143.7623 | O14: =IF($I14-AE$24<0, 0, ($I14-AE$24)*$G14) -> 4143.7623 | P14: =IF($I14-AF$24<0, 0, ($I14-AF$24)*$G14) -> 7266.05 | Q14: =IF($I14-AG$24<0, 0, ($I14-AG$24)*$G14) -> 7266.05 | ... U14: =IF($I14-AK$24<0, 0, ($I14-AK$24)*$G14) -> 6627.166 | V14: =MAX(J14:U14) -> 7266.05 | Y14: Nov | Z14: Rabi | AA14: 2.27 | AB14: 2 | AC14: =AA14+AB14 -> 4.27 | AD14: =AC14*30 -> 128.1 | AE14: =AD14/1000 -> 0.1281 | AF14: =AE14 -> 0.1281
A15: 12 | B15: 20.0189 | C15: 84.9893 | D15: Lakes/Ponds | E15: NA | F15: 2 | G15: 465.72 | H15: Jaringi | I15: =F15-$AC$20 -> 1.75 | J15: =IF($I15-Z$24<0, 0, ($I15-Z$24)*$G15) -> 643.15932 | K15: =IF($I15-AA$24<0, 0, ($I15-AA$24)*$G15) -> 563.80063 | L15: =IF($I15-AB$24<0, 0, ($I15-AB$24)*$G15) -> 471.58807 | M15: =IF($I15-AC$24<0, 0, ($I15-AC$24)*$G15) -> 376.16204 | N15: =IF($I15-AD$24<0, 0, ($I15-AD$24)*$G15) -> 264.66868 | O15: =IF($I15-AE$24<0, 0, ($I15-AE$24)*$G15) -> 264.66868 | P15: =IF($I15-AF$24<0, 0, ($I15-AF$24)*$G15) -> 815.01 | Q15: =IF($I15-AG$24<0, 0, ($I15-AG$24)*$G15) -> 815.01 | ... U15: =IF($I15-AK$24<0, 0, ($I15-AK$24)*$G15) -> 702.3989 | V15: =MAX(J15:U15) -> 815.01 | Y15: Dec | Z15: Rabi | AA15: 1.79 | AB15: 2 | AC15: =AA15+AB15 -> 3.79 | AD15: =AC15*30 -> 113.7 | AE15: =AD15/1000 -> 0.1137 | AF15: =AE14+AE15 -> 0.2418
A16: 13 | B16: 20.0229 | C16: 84.9846 | D16: Lakes/Ponds | E16: NA | F16: 4 | G16: 14807.55 | H16: Jaringi | I16: =F16-$AC$20 -> 3.75 | J16: =IF($I16-Z$24<0, 0, ($I16-Z$24)*$G16) -> 50064.327 | K16: =IF($I16-AA$24<0, 0, ($I16-AA$24)*$G16) -> 47541.12 | L16: =IF($I16-AB$24<0, 0, ($I16-AB$24)*$G16) -> 44609.225 | M16: =IF($I16-AC$24<0, 0, ($I16-AC$24)*$G16) -> 41575.158 | N16: =IF($I16-AD$24<0, 0, ($I16-AD$24)*$G16) -> 38030.231 | O16: =IF($I16-AE$24<0, 0, ($I16-AE$24)*$G16) -> 38030.231 | P16: =IF($I16-AF$24<0, 0, ($I16-AF$24)*$G16) -> 55528.312 | Q16: =IF($I16-AG$24<0, 0, ($I16-AG$24)*$G16) -> 55528.312 | ... U16: =IF($I16-AK$24<0, 0, ($I16-AK$24)*$G16) -> 51947.847 | V16: =MAX(J16:U16) -> 55528.312
A17: 14 | B17: 20.0242 | C17: 84.9833 | D17: Lakes/Ponds | E17: NA | F17: 3.5 | G17: 8632.09 | H17: Jaringi | I17: =F17-$AC$20 -> 3.25 | J17: =IF($I17-Z$24<0, 0, ($I17-Z$24)*$G17) -> 24869.051 | K17: =IF($I17-AA$24<0, 0, ($I17-AA$24)*$G17) -> 23398.143 | L17: =IF($I17-AB$24<0, 0, ($I17-AB$24)*$G17) -> 21688.989 | M17: =IF($I17-AC$24<0, 0, ($I17-AC$24)*$G17) -> 19920.274 | N17: =IF($I17-AD$24<0, 0, ($I17-AD$24)*$G17) -> 17853.752 | O17: =IF($I17-AE$24<0, 0, ($I17-AE$24)*$G17) -> 17853.752 | P17: =IF($I17-AF$24<0, 0, ($I17-AF$24)*$G17) -> 28054.292 | Q17: =IF($I17-AG$24<0, 0, ($I17-AG$24)*$G17) -> 28054.292 | ... U17: =IF($I17-AK$24<0, 0, ($I17-AK$24)*$G17) -> 25967.053 | V17: =MAX(J17:U17) -> 28054.292
A18: 15 | B18: 20.0237 | C18: 84.9869 | D18: Lakes/Ponds | E18: NA | F18: 2 | G18: 425.84 | H18: Jaringi | I18: =F18-$AC$20 -> 1.75 | J18: =IF($I18-Z$24<0, 0, ($I18-Z$24)*$G18) -> 588.08504 | K18: =IF($I18-AA$24<0, 0, ($I18-AA$24)*$G18) -> 515.5219 | L18: =IF($I18-AB$24<0, 0, ($I18-AB$24)*$G18) -> 431.20558 | M18: =IF($I18-AC$24<0, 0, ($I18-AC$24)*$G18) -> 343.95097 | N18: =IF($I18-AD$24<0, 0, ($I18-AD$24)*$G18) -> 242.00487 | O18: =IF($I18-AE$24<0, 0, ($I18-AE$24)*$G18) -> 242.00487 | P18: =IF($I18-AF$24<0, 0, ($I18-AF$24)*$G18) -> 745.22 | Q18: =IF($I18-AG$24<0, 0, ($I18-AG$24)*$G18) -> 745.22 | ... U18: =IF($I18-AK$24<0, 0, ($I18-AK$24)*$G18) -> 642.25189 | V18: =MAX(J18:U18) -> 745.22
A19: 16 | B19: 20.0253 | C19: 84.9868 | D19: Lakes/Ponds | E19: NA | F19: 2 | G19: 3644.58 | H19: Jaringi | I19: =F19-$AC$20 -> 1.75 | J19: =IF($I19-Z$24<0, 0, ($I19-Z$24)*$G19) -> 5033.165 | K19: =IF($I19-AA$24<0, 0, ($I19-AA$24)*$G19) -> 4412.1285 | L19: =IF($I19-AB$24<0, 0, ($I19-AB$24)*$G19) -> 3690.5017 | M19: =IF($I19-AC$24<0, 0, ($I19-AC$24)*$G19) -> 2943.7273 | N19: =IF($I19-AD$24<0, 0, ($I19-AD$24)*$G19) -> 2071.2148 | O19: =IF($I19-AE$24<0, 0, ($I19-AE$24)*$G19) -> 2071.2148 | P19: =IF($I19-AF$24<0, 0, ($I19-AF$24)*$G19) -> 6378.015 | Q19: =IF($I19-AG$24<0, 0, ($I19-AG$24)*$G19) -> 6378.015 | ... U19: =IF($I19-AK$24<0, 0, ($I19-AK$24)*$G19) -> 5496.7556 | V19: =MAX(J19:U19) -> 6378.015
A20: 17 | B20: 20.0337 | C20: 84.9676 | D20: Lakes/Ponds | E20: NA | F20: 3 | G20: 342.3 | H20: Khubhiapalli | I20: =F20-$AC$20 -> 2.75 | J20: =IF($I20-Z$24<0, 0, ($I20-Z$24)*$G20) -> 815.0163 | K20: =IF($I20-AA$24<0, 0, ($I20-AA$24)*$G20) -> 756.68838 | L20: =IF($I20-AB$24<0, 0, ($I20-AB$24)*$G20) -> 688.91298 | M20: =IF($I20-AC$24<0, 0, ($I20-AC$24)*$G20) -> 618.77571 | N20: =IF($I20-AD$24<0, 0, ($I20-AD$24)*$G20) -> 536.82909 | O20: =IF($I20-AE$24<0, 0, ($I20-AE$24)*$G20) -> 536.82909 | P20: =IF($I20-AF$24<0, 0, ($I20-AF$24)*$G20) -> 941.325 | Q20: =IF($I20-AG$24<0, 0, ($I20-AG$24)*$G20) -> 941.325 | ... U20: =IF($I20-AK$24<0, 0, ($I20-AK$24)*$G20) -> 858.55686 | V20: =MAX(J20:U20) -> 941.325 | AB20: Safe factor | AC20: 0.25
A21: 18 | B21: 20.0328 | C21: 84.9643 | D21: Lakes/Ponds | E21: NA | F21: 4 | G21: 7292.52 | H21: Khubhiapalli | I21: =F21-$AC$20 -> 3.75 | J21: =IF($I21-Z$24<0, 0, ($I21-Z$24)*$G21) -> 24656.01 | K21: =IF($I21-AA$24<0, 0, ($I21-AA$24)*$G21) -> 23413.365 | L21: =IF($I21-AB$24<0, 0, ($I21-AB$24)*$G21) -> 21969.446 | M21: =IF($I21-AC$24<0, 0, ($I21-AC$24)*$G21) -> 20475.208 | N21: =IF($I21-AD$24<0, 0, ($I21-AD$24)*$G21) -> 18729.379 | O21: =IF($I21-AE$24<0, 0, ($I21-AE$24)*$G21) -> 18729.379 | P21: =IF($I21-AF$24<0, 0, ($I21-AF$24)*$G21) -> 27346.95 | Q21: =IF($I21-AG$24<0, 0, ($I21-AG$24)*$G21) -> 27346.95 | ... U21: =IF($I21-AK$24<0, 0, ($I21-AK$24)*$G21) -> 25583.619 | V21: =MAX(J21:U21) -> 27346.95
A22: 19 | B22: 20.0304 | C22: 84.9687 | D22: Lakes/Ponds | E22: NA | F22: 3.5 | G22: 7901.06 | H22: Khubhiapalli | I22: =F22-$AC$20 -> 3.25 | J22: =IF($I22-Z$24<0, 0, ($I22-Z$24)*$G22) -> 22762.954 | K22: =IF($I22-AA$24<0, 0, ($I22-AA$24)*$G22) -> 21416.613 | L22: =IF($I22-AB$24<0, 0, ($I22-AB$24)*$G22) -> 19852.203 | M22: =IF($I22-AC$24<0, 0, ($I22-AC$24)*$G22) -> 18233.276 | N22: =IF($I22-AD$24<0, 0, ($I22-AD$24)*$G22) -> 16341.762 | O22: =IF($I22-AE$24<0, 0, ($I22-AE$24)*$G22) -> 16341.762 | P22: =IF($I22-AF$24<0, 0, ($I22-AF$24)*$G22) -> 25678.445 | Q22: =IF($I22-AG$24<0, 0, ($I22-AG$24)*$G22) -> 25678.445 | ... U22: =IF($I22-AK$24<0, 0, ($I22-AK$24)*$G22) -> 23767.969 | V22: =MAX(J22:U22) -> 25678.445
A23: 20 | B23: 20.0299 | C23: 84.964 | D23: Lakes/Ponds | E23: NA | F23: 3 | G23: 2098.08 | H23: Khubhiapalli | I23: =F23-$AC$20 -> 2.75 | J23: =IF($I23-Z$24<0, 0, ($I23-Z$24)*$G23) -> 4995.5285 | K23: =IF($I23-AA$24<0, 0, ($I23-AA$24)*$G23) -> 4638.0156 | L23: =IF($I23-AB$24<0, 0, ($I23-AB$24)*$G23) -> 4222.5958 | M23: =IF($I23-AC$24<0, 0, ($I23-AC$24)*$G23) -> 3792.6992 | N23: =IF($I23-AD$24<0, 0, ($I23-AD$24)*$G23) -> 3290.4189 | O23: =IF($I23-AE$24<0, 0, ($I23-AE$24)*$G23) -> 3290.4189 | P23: =IF($I23-AF$24<0, 0, ($I23-AF$24)*$G23) -> 5769.72 | Q23: =IF($I23-AG$24<0, 0, ($I23-AG$24)*$G23) -> 5769.72 | ... U23: =IF($I23-AK$24<0, 0, ($I23-AK$24)*$G23) -> 5262.4043 | V23: =MAX(J23:U23) -> 5769.72 | Y23: Month | Z23: Jan | AA23: Feb | AB23: Mar | AC23: Apr | AD23: May | AE23: Jun | AF23: Jul | AG23: Aug | AH23: Sep | AI23: Oct | AJ23: Nov | AK23: Dec
A24: 21 | B24: 20.0235 | C24: 84.9634 | D24: Lakes/Ponds | E24: NA | F24: 4 | G24: 1914.1 | H24: Khubhiapalli | I24: =F24-$AC$20 -> 3.75 | J24: =IF($I24-Z$24<0, 0, ($I24-Z$24)*$G24) -> 6471.5721 | K24: =IF($I24-AA$24<0, 0, ($I24-AA$24)*$G24) -> 6145.4095 | L24: =IF($I24-AB$24<0, 0, ($I24-AB$24)*$G24) -> 5766.4177 | M24: =IF($I24-AC$24<0, 0, ($I24-AC$24)*$G24) -> 5374.2186 | N24: =IF($I24-AD$24<0, 0, ($I24-AD$24)*$G24) -> 4915.983 | O24: =IF($I24-AE$24<0, 0, ($I24-AE$24)*$G24) -> 4915.983 | P24: =IF($I24-AF$24<0, 0, ($I24-AF$24)*$G24) -> 7177.875 | Q24: =IF($I24-AG$24<0, 0, ($I24-AG$24)*$G24) -> 7177.875 | ... U24: =IF($I24-AK$24<0, 0, ($I24-AK$24)*$G24) -> 6715.0456 | V24: =MAX(J24:U24) -> 7177.875 | Y24: Total cummulative loss (m/month) | Z24: =AF4 -> 0.369 | AA24: =AF5 -> 0.5394 | AB24: =AF6 -> 0.7374 | AC24: =AF7 -> 0.9423 | AD24: =AF8 -> 1.1817 | AE24: =AF9 -> 1.1817 | AF24: =AF10 -> 0 | AG24: =AF11 -> 0 | AH24: =AF12 -> 0 | AI24: =AF13 -> 0 | AJ24: =AF14 -> 0.1281 | AK24: =AF15 -> 0.2418
A25: 22 | B25: 20.0236 | C25: 84.9667 | D25: Lakes/Ponds | E25: NA | F25: 4 | G25: 8725.32 | H25: Khubhiapalli | I25: =F25-$AC$20 -> 3.75 | J25: =IF($I25-Z$24<0, 0, ($I25-Z$24)*$G25) -> 29500.307 | K25: =IF($I25-AA$24<0, 0, ($I25-AA$24)*$G25) -> 28013.512 | L25: =IF($I25-AB$24<0, 0, ($I25-AB$24)*$G25) -> 26285.899 | M25: =IF($I25-AC$24<0, 0, ($I25-AC$24)*$G25) -> 24498.081 | N25: =IF($I25-AD$24<0, 0, ($I25-AD$24)*$G25) -> 22409.239 | O25: =IF($I25-AE$24<0, 0, ($I25-AE$24)*$G25) -> 22409.239 | P25: =IF($I25-AF$24<0, 0, ($I25-AF$24)*$G25) -> 32719.95 | Q25: =IF($I25-AG$24<0, 0, ($I25-AG$24)*$G25) -> 32719.95 | ... U25: =IF($I25-AK$24<0, 0, ($I25-AK$24)*$G25) -> 30610.168 | V25: =MAX(J25:U25) -> 32719.95
A26: 23 | B26: 20.0226 | C26: 84.976 | D26: Lakes/Ponds | E26: NA | F26: 4 | G26: 50782.82 | H26: Odagaon | I26: =F26-$AC$20 -> 3.75 | J26: =IF($I26-Z$24<0, 0, ($I26-Z$24)*$G26) -> 171696.71 | K26: =IF($I26-AA$24<0, 0, ($I26-AA$24)*$G26) -> 163043.32 | L26: =IF($I26-AB$24<0, 0, ($I26-AB$24)*$G26) -> 152988.32 | M26: =IF($I26-AC$24<0, 0, ($I26-AC$24)*$G26) -> 142582.92 | N26: =IF($I26-AD$24<0, 0, ($I26-AD$24)*$G26) -> 130425.52 | O26: =IF($I26-AE$24<0, 0, ($I26-AE$24)*$G26) -> 130425.52 | P26: =IF($I26-AF$24<0, 0, ($I26-AF$24)*$G26) -> 190435.58 | Q26: =IF($I26-AG$24<0, 0, ($I26-AG$24)*$G26) -> 190435.58 | ... U26: =IF($I26-AK$24<0, 0, ($I26-AK$24)*$G26) -> 178156.29 | V26: =MAX(J26:U26) -> 190435.58
A27: 24 | B27: 20.0148 | C27: 84.9656 | D27: Lakes/Ponds | E27: NA | F27: 3 | G27: 14540.93 | H27: Khubhiapalli | I27: =F27-$AC$20 -> 2.75 | J27: =IF($I27-Z$24<0, 0, ($I27-Z$24)*$G27) -> 34621.954 | K27: =IF($I27-AA$24<0, 0, ($I27-AA$24)*$G27) -> 32144.18 | L27: =IF($I27-AB$24<0, 0, ($I27-AB$24)*$G27) -> 29265.076 | M27: =IF($I27-AC$24<0, 0, ($I27-AC$24)*$G27) -> 26285.639 | N27: =IF($I27-AD$24<0, 0, ($I27-AD$24)*$G27) -> 22804.541 | O27: =IF($I27-AE$24<0, 0, ($I27-AE$24)*$G27) -> 22804.541 | P27: =IF($I27-AF$24<0, 0, ($I27-AF$24)*$G27) -> 39987.558 | Q27: =IF($I27-AG$24<0, 0, ($I27-AG$24)*$G27) -> 39987.558 | ... U27: =IF($I27-AK$24<0, 0, ($I27-AK$24)*$G27) -> 36471.561 | V27: =MAX(J27:U27) -> 39987.558
A28: 25 | B28: 20.0075 | C28: 84.9658 | D28: Lakes/Ponds | E28: NA | F28: 2 | G28: 1837.4 | H28: Khubhiapalli | I28: =F28-$AC$20 -> 1.75 | J28: =IF($I28-Z$24<0, 0, ($I28-Z$24)*$G28) -> 2537.4494 | K28: =IF($I28-AA$24<0, 0, ($I28-AA$24)*$G28) -> 2224.3564 | L28: =IF($I28-AB$24<0, 0, ($I28-AB$24)*$G28) -> 1860.5512 | M28: =IF($I28-AC$24<0, 0, ($I28-AC$24)*$G28) -> 1484.068 | N28: =IF($I28-AD$24<0, 0, ($I28-AD$24)*$G28) -> 1044.1944 | O28: =IF($I28-AE$24<0, 0, ($I28-AE$24)*$G28) -> 1044.1944 | P28: =IF($I28-AF$24<0, 0, ($I28-AF$24)*$G28) -> 3215.45 | Q28: =IF($I28-AG$24<0, 0, ($I28-AG$24)*$G28) -> 3215.45 | ... U28: =IF($I28-AK$24<0, 0, ($I28-AK$24)*$G28) -> 2771.1667 | V28: =MAX(J28:U28) -> 3215.45
A29: 26 | B29: 20.0069 | C29: 84.9659 | D29: Lakes/Ponds | E29: NA | F29: 3 | G29: 6228.45 | H29: Khubhiapalli | I29: =F29-$AC$20 -> 2.75 | J29: =IF($I29-Z$24<0, 0, ($I29-Z$24)*$G29) -> 14829.939 | K29: =IF($I29-AA$24<0, 0, ($I29-AA$24)*$G29) -> 13768.612 | L29: =IF($I29-AB$24<0, 0, ($I29-AB$24)*$G29) -> 12535.378 | M29: =IF($I29-AC$24<0, 0, ($I29-AC$24)*$G29) -> 11259.169 | N29: =IF($I29-AD$24<0, 0, ($I29-AD$24)*$G29) -> 9768.0781 | O29: =IF($I29-AE$24<0, 0, ($I29-AE$24)*$G29) -> 9768.0781 | P29: =IF($I29-AF$24<0, 0, ($I29-AF$24)*$G29) -> 17128.237 | Q29: =IF($I29-AG$24<0, 0, ($I29-AG$24)*$G29) -> 17128.237 | ... U29: =IF($I29-AK$24<0, 0, ($I29-AK$24)*$G29) -> 15622.198 | V29: =MAX(J29:U29) -> 17128.237
A30: 27 | B30: 20.0063 | C30: 84.9665 | D30: Lakes/Ponds | E30: NA | F30: 2 | G30: 3637.72 | H30: Khubhiapalli | I30: =F30-$AC$20 -> 1.75 | J30: =IF($I30-Z$24<0, 0, ($I30-Z$24)*$G30) -> 5023.6913 | K30: =IF($I30-AA$24<0, 0, ($I30-AA$24)*$G30) -> 4403.8238 | L30: =IF($I30-AB$24<0, 0, ($I30-AB$24)*$G30) -> 3683.5553 | M30: =IF($I30-AC$24<0, 0, ($I30-AC$24)*$G30) -> 2938.1864 | N30: =IF($I30-AD$24<0, 0, ($I30-AD$24)*$G30) -> 2067.3163 | O30: =IF($I30-AE$24<0, 0, ($I30-AE$24)*$G30) -> 2067.3163 | P30: =IF($I30-AF$24<0, 0, ($I30-AF$24)*$G30) -> 6366.01 | Q30: =IF($I30-AG$24<0, 0, ($I30-AG$24)*$G30) -> 6366.01 | ... U30: =IF($I30-AK$24<0, 0, ($I30-AK$24)*$G30) -> 5486.4093 | V30: =MAX(J30:U30) -> 6366.01
A31: 28 | B31: 20.0063 | C31: 84.9693 | D31: Lakes/Ponds | E31: NA | F31: 2 | G31: 721.48 | H31: Khubhiapalli | I31: =F31-$AC$20 -> 1.75 | J31: =IF($I31-Z$24<0, 0, ($I31-Z$24)*$G31) -> 996.36388 | K31: =IF($I31-AA$24<0, 0, ($I31-AA$24)*$G31) -> 873.42369 | L31: =IF($I31-AB$24<0, 0, ($I31-AB$24)*$G31) -> 730.57065 | M31: =IF($I31-AC$24<0, 0, ($I31-AC$24)*$G31) -> 582.7394 | N31: =IF($I31-AD$24<0, 0, ($I31-AD$24)*$G31) -> 410.01708 | O31: =IF($I31-AE$24<0, 0, ($I31-AE$24)*$G31) -> 410.01708 | P31: =IF($I31-AF$24<0, 0, ($I31-AF$24)*$G31) -> 1262.59 | Q31: =IF($I31-AG$24<0, 0, ($I31-AG$24)*$G31) -> 1262.59 | ... U31: =IF($I31-AK$24<0, 0, ($I31-AK$24)*$G31) -> 1088.1361 | V31: =MAX(J31:U31) -> 1262.59
A32: 29 | B32: 20.0049 | C32: 84.971 | D32: Lakes/Ponds | E32: NA | F32: 2 | G32: 549.59 | H32: Khubhiapalli | I32: =F32-$AC$20 -> 1.75 | J32: =IF($I32-Z$24<0, 0, ($I32-Z$24)*$G32) -> 758.98379 | K32: =IF($I32-AA$24<0, 0, ($I32-AA$24)*$G32) -> 665.33365 | L32: =IF($I32-AB$24<0, 0, ($I32-AB$24)*$G32) -> 556.51483 | M32: =IF($I32-AC$24<0, 0, ($I32-AC$24)*$G32) -> 443.90384 | N32: =IF($I32-AD$24<0, 0, ($I32-AD$24)*$G32) -> 312.332 | O32: =IF($I32-AE$24<0, 0, ($I32-AE$24)*$G32) -> 312.332 | P32: =IF($I32-AF$24<0, 0, ($I32-AF$24)*$G32) -> 961.7825 | Q32: =IF($I32-AG$24<0, 0, ($I32-AG$24)*$G32) -> 961.7825 | ... U32: =IF($I32-AK$24<0, 0, ($I32-AK$24)*$G32) -> 828.89164 | V32: =MAX(J32:U32) -> 961.7825
A33: 30 | B33: 19.9992 | C33: 84.9722 | D33: Lakes/Ponds | E33: NA | F33: 4 | G33: 8715.41 | H33: Khubhiapalli | I33: =F33-$AC$20 -> 3.75 | J33: =IF($I33-Z$24<0, 0, ($I33-Z$24)*$G33) -> 29466.801 | K33: =IF($I33-AA$24<0, 0, ($I33-AA$24)*$G33) -> 27981.695 | L33: =IF($I33-AB$24<0, 0, ($I33-AB$24)*$G33) -> 26256.044 | M33: =IF($I33-AC$24<0, 0, ($I33-AC$24)*$G33) -> 24470.257 | N33: =IF($I33-AD$24<0, 0, ($I33-AD$24)*$G33) -> 22383.788 | O33: =IF($I33-AE$24<0, 0, ($I33-AE$24)*$G33) -> 22383.788 | P33: =IF($I33-AF$24<0, 0, ($I33-AF$24)*$G33) -> 32682.787 | Q33: =IF($I33-AG$24<0, 0, ($I33-AG$24)*$G33) -> 32682.787 | ... U33: =IF($I33-AK$24<0, 0, ($I33-AK$24)*$G33) -> 30575.401 | V33: =MAX(J33:U33) -> 32682.787
A34: 31 | B34: 19.9964 | C34: 84.9729 | D34: Lakes/Ponds | E34: NA | F34: 4 | G34: 1121.71 | H34: Khubhiapalli | I34: =F34-$AC$20 -> 3.75 | J34: =IF($I34-Z$24<0, 0, ($I34-Z$24)*$G34) -> 3792.5015 | K34: =IF($I34-AA$24<0, 0, ($I34-AA$24)*$G34) -> 3601.3621 | L34: =IF($I34-AB$24<0, 0, ($I34-AB$24)*$G34) -> 3379.2635 | M34: =IF($I34-AC$24<0, 0, ($I34-AC$24)*$G34) -> 3149.4252 | N34: =IF($I34-AD$24<0, 0, ($I34-AD$24)*$G34) -> 2880.8878 | O34: =IF($I34-AE$24<0, 0, ($I34-AE$24)*$G34) -> 2880.8878 | P34: =IF($I34-AF$24<0, 0, ($I34-AF$24)*$G34) -> 4206.4125 | Q34: =IF($I34-AG$24<0, 0, ($I34-AG$24)*$G34) -> 4206.4125 | ... U34: =IF($I34-AK$24<0, 0, ($I34-AK$24)*$G34) -> 3935.183 | V34: =MAX(J34:U34) -> 4206.4125
A35: 32 | B35: 19.992 | C35: 84.9736 | D35: Lakes/Ponds | E35: NA | F35: 3 | G35: 2199.67 | H35: Khubhiapalli | I35: =F35-$AC$20 -> 2.75 | J35: =IF($I35-Z$24<0, 0, ($I35-Z$24)*$G35) -> 5237.4143 | K35: =IF($I35-AA$24<0, 0, ($I35-AA$24)*$G35) -> 4862.5905 | L35: =IF($I35-AB$24<0, 0, ($I35-AB$24)*$G35) -> 4427.0558 | M35: =IF($I35-AC$24<0, 0, ($I35-AC$24)*$G35) -> 3976.3435 | N35: =IF($I35-AD$24<0, 0, ($I35-AD$24)*$G35) -> 3449.7425 | O35: =IF($I35-AE$24<0, 0, ($I35-AE$24)*$G35) -> 3449.7425 | P35: =IF($I35-AF$24<0, 0, ($I35-AF$24)*$G35) -> 6049.0925 | Q35: =IF($I35-AG$24<0, 0, ($I35-AG$24)*$G35) -> 6049.0925 | ... U35: =IF($I35-AK$24<0, 0, ($I35-AK$24)*$G35) -> 5517.2123 | V35: =MAX(J35:U35) -> 6049.0925
A36: 33 | B36: 19.9926 | C36: 84.9731 | D36: Lakes/Ponds | E36: NA | F36: 3 | G36: 877.95 | H36: Khubhiapalli | I36: =F36-$AC$20 -> 2.75 | J36: =IF($I36-Z$24<0, 0, ($I36-Z$24)*$G36) -> 2090.399 | K36: =IF($I36-AA$24<0, 0, ($I36-AA$24)*$G36) -> 1940.7963 | L36: =IF($I36-AB$24<0, 0, ($I36-AB$24)*$G36) -> 1766.9622 | M36: =IF($I36-AC$24<0, 0, ($I36-AC$24)*$G36) -> 1587.0702 | N36: =IF($I36-AD$24<0, 0, ($I36-AD$24)*$G36) -> 1376.889 | O36: =IF($I36-AE$24<0, 0, ($I36-AE$24)*$G36) -> 1376.889 | P36: =IF($I36-AF$24<0, 0, ($I36-AF$24)*$G36) -> 2414.3625 | Q36: =IF($I36-AG$24<0, 0, ($I36-AG$24)*$G36) -> 2414.3625 | ... U36: =IF($I36-AK$24<0, 0, ($I36-AK$24)*$G36) -> 2202.0742 | V36: =MAX(J36:U36) -> 2414.3625
... A297: 295 | B297: 20.04514 | C297: 85.03555 | D297: Reservoir/MCD | E297: Saradhapur_MCD | F297: 1 | G297: 316.9608 | H297: Saradapur | I297: =F297-$AC$20 -> 0.75 | J297: =IF($I297-Z$24<0, 0, ($I297-Z$24)*$G297) -> 120.76206 | K297: =IF($I297-AA$24<0, 0, ($I297-AA$24)*$G297) -> 66.751944 | L297: =IF($I297-AB$24<0, 0, ($I297-AB$24)*$G297) -> 3.9937061 | M297: =IF($I297-AC$24<0, 0, ($I297-AC$24)*$G297) -> 0 | N297: =IF($I297-AD$24<0, 0, ($I297-AD$24)*$G297) -> 0 | O297: =IF($I297-AE$24<0, 0, ($I297-AE$24)*$G297) -> 0 | P297: =IF($I297-AF$24<0, 0, ($I297-AF$24)*$G297) -> 237.7206 | Q297: =IF($I297-AG$24<0, 0, ($I297-AG$24)*$G297) -> 237.7206 | ... U297: =IF($I297-AK$24<0, 0, ($I297-AK$24)*$G297) -> 161.07948 | V297: =MAX(J297:U297) -> 237.7206
V298: =SUM(V3:V297) -> 4113643.4
J299: Jan | K299: Feb | L299: Mar | M299: Apr | N299: May | O299: Jun | P299: Jul | Q299: Aug | R299: Sep | S299: Oct | T299: Nov | U299: Dec
F300: Lakes/Ponds | J300: =SUM(J3:J285) -> 3622916.8 | K300: =SUM(K3:K285) -> 3401980.4 | L300: =SUM(L3:L285) -> 3145258.6 | M300: =SUM(M3:M285) -> 2879590.3 | N300: =SUM(N3:N285) -> 2569190.3 | O300: =SUM(O3:O285) -> 2569190.3 | P300: =SUM(P3:P285) -> 4101353 | Q300: =SUM(Q3:Q285) -> 4101353 | ... U300: =SUM(U3:U285) -> 3787841.2 | V300: =SUM(J300:U300) -> 42316642
...

Sheet Odogaon_33
A1: FID | B1: Latitude | C1: Longitude | D1: Category | E1: Name | F1: Depth_m | G1: Area_m2 | H1: MWS Name | I1: Depth_m (after deducting safe factor) | J1: Jan | K1: Feb | L1: Mar | M1: Apr | N1: May | O1: Jun | P1: Jul | Q1: Aug | R1: Sep | S1: Oct | T1: Nov | U1: Dec
A2: 0 | B2: 20.0375 | C2: 85.1137 | D2: Lakes/Ponds | E2: NA | F2: 2 | G2: 224.24 | H2: Sikharpur | I2: 1.75 | J2: 309.67544 | K2: 271.46494 | L2: 227.06542 | M2: 181.11865 | N2: 127.43559 | O2: 127.43559 | P2: 392.42 | Q2: 392.42 | R2: 392.42 | S2: 392.42 | T2: 363.69486 | U2: 338.19877 | W2: Count of Depth_m | X2: Column Labels
A3: 1 | B3: 20.0123 | C3: 85.0825 | D3: Lakes/Ponds | E3: NA | F3: 2 | G3: 240.41 | H3: Dhusuma | I3: 1.75 | J3: 332.00621 | K3: 291.04035 | L3: 243.43917 | M3: 194.17916 | N3: 136.625 | O3: 136.625 | P3: 420.7175 | Q3: 420.7175 | R3: 420.7175 | S3: 420.7175 | T3: 389.92098 | U3: 362.58636 | W3: Row Labels | X3: Lakes/Ponds | Y3: Reservoir/MCD | Z3: Grand Total
A4: 2 | B4: 20.0379 | C4: 85.1134 | D4: Lakes/Ponds | E4: NA | F4: 2 | G4: 402.31 | H4: Sikharpur | I4: 1.75 | J4: 555.59011 | K4: 487.03649 | L4: 407.37911 | M4: 324.94579 | N4: 228.63277 | O4: 228.63277 | P4: 704.0425 | Q4: 704.0425 | R4: 704.0425 | S4: 704.0425 | T4: 652.50659 | U4: 606.76394 | W4: Badagarada | X4: 27 | Z4: 27
A5: 3 | B5: 20.0108 | C5: 85.0825 | D5: Lakes/Ponds | E5: NA | F5: 3 | G5: 2124.01 | H5: Dhusuma | I5: 2.75 | J5: 5057.2678 | K5: 4695.3365 | L5: 4274.7825 | M5: 3839.5729 | N5: 3331.0849 | O5: 3331.0849 | P5: 5841.0275 | Q5: 5841.0275 | R5: 5841.0275 | S5: 5841.0275 | T5: 5568.9418 | U5: 5327.4419 | W5: Badaput | X5: 24 | Y5: 1 | Z5: 25
A6: 4 | B6: 20.0385 | C6: 85.1135 | D6: Lakes/Ponds | E6: NA | F6: 2 | G6: 245.48 | H6: Sikharpur | I6: 1.75 | J6: 339.00788 | K6: 297.17809 | L6: 248.57305 | M6: 198.2742 | N6: 139.50628 | O6: 139.50628 | P6: 429.59 | Q6: 429.59 | R6: 429.59 | S6: 429.59 | T6: 398.14401 | U6: 370.23294 | W6: Bhandar | X6: 19 | Z6: 19
A7: 5 | B7: 20.0391 | C7: 85.1135 | D7: Lakes/Ponds | E7: NA | F7: 2 | G7: 295.2 | H7: Sikharpur | I7: 1.75 | J7: 407.6712 | K7: 357.36912 | L7: 298.91952 | M7: 238.43304 | N7: 167.76216 | O7: 167.76216 | P7: 516.6 | Q7: 516.6 | R7: 516.6 | S7: 516.6 | T7: 478.78488 | U7: 445.22064 | W7: Dhusuma | X7: 18 | Y7: 1 | Z7: 19
A8: 6 | B8: 20.0315 | C8: 85.101 | D8: Lakes/Ponds | E8: NA | F8: 2 | G8: 101.13 | H8: Sikharpur | I8: 1.75 | J8: 139.66053 | K8: 122.42798 | L8: 102.40424 | M8: 81.682701 | N8: 57.472179 | O8: 57.472179 | P8: 176.9775 | Q8: 176.9775 | R8: 176.9775 | S8: 176.9775 | T8: 164.02275 | U8: 152.52427 | W8: Jaringi | X8: 18 | Y8: 1 | Z8: 19
A9: 7 | B9: 20.0379 | C9: 84.967 | D9: Lakes/Ponds | E9: NA | F9: 2 | G9: 325.86 | H9: Khubhiapalli | I9: 1.75 | J9: 450.01266 | K9: 394.48612 | L9: 329.96584 | M9: 263.19712 | N9: 185.18624 | O9: 185.18624 | P9: 570.255 | Q9: 570.255 | R9: 570.255 | S9: 570.255 | T9: 528.51233 | U9: 491.46205 | W9: Kalyanpur | X9: 17 | Y9: 1 | Z9: 18
A10: 8 | B10: 20.0457 | C10: 85.0313 | D10: Lakes/Ponds | E10: NA | F10: 2 | G10: 830.15 | H10: Saradapur | I10: 1.75 | J10: 1146.4371 | K10: 1004.9796 | L10: 840.60989 | M10: 670.51216 | N10: 471.77425 | O10: 471.77425 | P10: 1452.7625 | Q10: 1452.7625 | R10: 1452.7625 | S10: 1452.7625 | T10: 1346.4203 | U10: 1252.0322 | W10: Khubhiapalli | X10: 24 | Z10: 24
A11: 9 | B11: 20.0091 | C11: 85.0076 | D11: Lakes/Ponds | E11: NA | F11: 3 | G11: 857.31 | H11: Rabara | I11: 2.75 | J11: 2041.2551 | K11: 1895.1695 | L11: 1725.4221 | M11: 1549.7593 | N11: 1344.5193 | O11: 1344.5193 | P11: 2357.6025 | Q11: 2357.6025 | R11: 2357.6025 | S11: 2357.6025 | T11: 2247.7811 | U11: 2150.3049 | W11: Nandighora | X11: 32 | Z11: 32
A12: 10 | B12: 20.0341 | C12: 84.9667 | D12: Lakes/Ponds | E12: NA | F12: 3 | G12: 4729.47 | H12: Khubhiapalli | I12: 2.75 | J12: 11260.868 | K12: 10454.966 | L12: 9518.5313 | M12: 8549.4629 | N12: 7417.2278 | O12: 7417.2278 | P12: 13006.043 | Q12: 13006.043 | R12: 13006.043 | S12: 13006.043 | T12: 12400.197 | U12: 11862.457 | W12: Odagaon | X12: 8 | Y12: 5 | Z12: 13
A13: 11 | B13: 20.0168 | C13: 84.9898 | D13: Lakes/Ponds | E13: NA | F13: 3 | G13: 2642.2 | H13: Jaringi | I13: 2.75 | J13: 6291.0782 | K13: 5840.8473 | L13: 5317.6917 | M13: 4776.3049 | N13: 4143.7623 | O13: 4143.7623 | P13: 7266.05 | Q13: 7266.05 | R13: 7266.05 | S13: 7266.05 | T13: 6927.5842 | U13: 6627.166 | W13: Rabara | X13: 31 | Y13: 2 | Z13: 33
A14: 12 | B14: 20.0189 | C14: 84.9893 | D14: Lakes/Ponds | E14: NA | F14: 2 | G14: 465.72 | H14: Jaringi | I14: 1.75 | J14: 643.15932 | K14: 563.80063 | L14: 471.58807 | M14: 376.16204 | N14: 264.66868 | O14: 264.66868 | P14: 815.01 | Q14: 815.01 | R14: 815.01 | S14: 815.01 | T14: 755.35127 | U14: 702.3989 | W14: Saradapur | X14: 36 | Y14: 1 | Z14: 37
A15: 13 | B15: 20.0229 | C15: 84.9846 | D15: Lakes/Ponds | E15: NA | F15: 4 | G15: 14807.55 | H15: Jaringi | I15: 3.75 | J15: 50064.327 | K15: 47541.12 | L15: 44609.225 | M15: 41575.158 | N15: 38030.231 | O15: 38030.231 | P15: 55528.312 | Q15: 55528.312 | R15: 55528.312 | S15: 55528.312 | T15: 53631.465 | U15: 51947.847 | W15: Sikharpur | X15: 29 | Z15: 29
A16: 14 | B16: 20.0242 | C16: 84.9833 | D16: Lakes/Ponds | E16: NA | F16: 3.5 | G16: 8632.09 | H16: Jaringi | I16: 3.25 | J16: 24869.051 | K16: 23398.143 | L16: 21688.989 | M16: 19920.274 | N16: 17853.752 | O16: 17853.752 | P16: 28054.292 | Q16: 28054.292 | R16: 28054.292 | S16: 28054.292 | T16: 26948.522 | U16: 25967.053 | W16: Grand Total | X16: 283 | Y16: 12 | Z16: 295
A17: 15 | B17: 20.0237 | C17: 84.9869 | D17: Lakes/Ponds | E17: NA | F17: 2 | G17: 425.84 | H17: Jaringi | I17: 1.75 | J17: 588.08504 | K17: 515.5219 | L17: 431.20558 | M17: 343.95097 | N17: 242.00487 | O17: 242.00487 | P17: 745.22 | Q17: 745.22 | R17: 745.22 | S17: 745.22 | T17: 690.6699 | U17: 642.25189
A18: 16 | B18: 20.0253 | C18: 84.9868 | D18: Lakes/Ponds | E18: NA | F18: 2 | G18: 3644.58 | H18: Jaringi | I18: 1.75 | J18: 5033.165 | K18: 4412.1285 | L18: 3690.5017 | M18: 2943.7273 | N18: 2071.2148 | O18: 2071.2148 | P18: 6378.015 | Q18: 6378.015 | R18: 6378.015 | S18: 6378.015 | T18: 5911.1443 | U18: 5496.7556
A19: 17 | B19: 20.0337 | C19: 84.9676 | D19: Lakes/Ponds | E19: NA | F19: 3 | G19: 342.3 | H19: Khubhiapalli | I19: 2.75 | J19: 815.0163 | K19: 756.68838 | L19: 688.91298 | M19: 618.77571 | N19: 536.82909 | O19: 536.82909 | P19: 941.325 | Q19: 941.325 | R19: 941.325 | S19: 941.325 | T19: 897.47637 | U19: 858.55686 | X19: Column Labels
A20: 18 | B20: 20.0328 | C20: 84.9643 | D20: Lakes/Ponds | E20: NA | F20: 4 | G20: 7292.52 | H20: Khubhiapalli | I20: 3.75 | J20: 24656.01 | K20: 23413.365 | L20: 21969.446 | M20: 20475.208 | N20: 18729.379 | O20: 18729.379 | P20: 27346.95 | Q20: 27346.95 | R20: 27346.95 | S20: 27346.95 | T20: 26412.778 | U20: 25583.619 | X20: Lakes/Ponds | AJ20: Reservoir/MCD | AV20: Total Sum of Jan | AW20: Total Sum of Feb | AX20: Total Sum of Mar | AY20: Total Sum of Apr | AZ20: Total Sum of May | BA20: Total Sum of Jun | BB20: Total Sum of Jul | BC20: Total Sum of Aug | BD20: Total Sum of Sep | BE20: Total Sum of Oct | BF20: Total Sum of Nov | BG20: Total Sum of Dec
A21: 19 | B21: 20.0304 | C21: 84.9687 | D21: Lakes/Ponds | E21: NA | F21: 3.5 | G21: 7901.06 | H21: Khubhiapalli | I21: 3.25 | J21: 22762.954 | K21: 21416.613 | L21: 19852.203 | M21: 18233.276 | N21: 16341.762 | O21: 16341.762 | P21: 25678.445 | Q21: 25678.445 | R21: 25678.445 | S21: 25678.445 | T21: 24666.319 | U21: 23767.969 | W21: Row Labels | X21: Sum of Jan | Y21: Sum of Feb | Z21: Sum of Mar | AA21: Sum of Apr | AB21: Sum of May | AC21: Sum of Jun | AD21: Sum of Jul | AE21: Sum of Aug | AF21: Sum of Sep | AG21: Sum of Oct | AH21: Sum of Nov | AI21: Sum of Dec | AJ21: Sum of Jan | AK21: Sum of Feb | AL21: Sum of Mar | AM21: Sum of Apr | AN21: Sum of May | AO21: Sum of Jun | AP21: Sum of Jul | AQ21: Sum of Aug | AR21: Sum of Sep | AS21: Sum of Oct | AT21: Sum of Nov | AU21: Sum of Dec
A22: 20 | B22: 20.0299 | C22: 84.964 | D22: Lakes/Ponds | E22: NA | F22: 3 | G22: 2098.08 | H22: Khubhiapalli | I22: 2.75 | J22: 4995.5285 | K22: 4638.0156 | L22: 4222.5958 | M22: 3792.6992 | N22: 3290.4189 | O22: 3290.4189 | P22: 5769.72 | Q22: 5769.72 | R22: 5769.72 | S22: 5769.72 | T22: 5500.956 | U22: 5262.4043 | W22: Badagarada | X22: 256369.69 | Y22: 239233.66 | Z22: 219322.08 | AA22: 198716.61 | AB22: 174641.7 | AC22: 174641.7 | AD22: 293477.64 | AE22: 293477.64 | AF22: 293477.64 | AG22: 293477.64 | AH22: 280595.45 | AI22: 269161.38 | AV22: 256369.69 | AW22: 239233.66 | AX22: 219322.08 | AY22: 198716.61 | AZ22: 174641.7 | BA22: 174641.7 | BB22: 293477.64 | BC22: 293477.64 | BD22: 293477.64 | BE22: 293477.64 | BF22: 280595.45 | BG22: 269161.38
A23: 21 | B23: 20.0235 | C23: 84.9634 | D23: Lakes/Ponds | E23: NA | F23: 4 | G23: 1914.1 | H23: Khubhiapalli | I23: 3.75 | J23: 6471.5721 | K23: 6145.4095 | L23: 5766.4177 | M23: 5374.2186 | N23: 4915.983 | O23: 4915.983 | P23: 7177.875 | Q23: 7177.875 | R23: 7177.875 | S23: 7177.875 | T23: 6932.6788 | U23: 6715.0456 | W23: Badaput | X23: 276576.45 | Y23: 259588.45 | Z23: 239848.87 | AA23: 219421.4 | AB23: 195554.46 | AC23: 195554.46 | AD23: 313363.84 | AE23: 313363.84 | AF23: 313363.84 | AG23: 313363.84 | AH23: 300592.93 | AI23: 289257.63 | AJ23: 0 | AK23: 0 | AL23: 0 | AM23: 0 | AN23: 0 | AO23: 0 | AP23: 2.8224055 | AQ23: 2.8224055 | AR23: 2.8224055 | AS23: 2.8224055 | AT23: 0 | AU23: 0 | AV23: 276576.45 | AW23: 259588.45 | AX23: 239848.87 | AY23: 219421.4 | AZ23: 195554.46 | BA23: 195554.46 | BB23: 313366.66 | BC23: 313366.66 | BD23: 313366.66 | BE23: 313366.66 | BF23: 300592.93 | BG23: 289257.63
A24: 22 | B24: 20.0236 | C24: 84.9667 | D24: Lakes/Ponds | E24: NA | F24: 4 | G24: 8725.32 | H24: Khubhiapalli | I24: 3.75 | J24: 29500.307 | K24: 28013.512 | L24: 26285.899 | M24: 24498.081 | N24: 22409.239 | O24: 22409.239 | P24: 32719.95 | Q24: 32719.95 | R24: 32719.95 | S24: 32719.95 | T24: 31602.237 | U24: 30610.168 | W24: Bhandar | X24: 216699.23 | Y24: 199585.75 | Z24: 179700.37 | AA24: 159122.01 | AB24: 135078.77 | AC24: 135078.77 | AD24: 253758.35 | AE24: 253758.35 | AF24: 253758.35 | AG24: 253758.35 | AH24: 240893.11 | AI24: 229474.08 | AV24: 216699.23 | AW24: 199585.75 | AX24: 179700.37 | AY24: 159122.01 | AZ24: 135078.77 | BA24: 135078.77 | BB24: 253758.35 | BC24: 253758.35 | BD24: 253758.35 | BE24: 253758.35 | BF24: 240893.11 | BG24: 229474.08
A25: 23 | B25: 20.0226 | C25: 84.976 | D25: Lakes/Ponds | E25: NA | F25: 4 | G25: 50782.82 | H25: Odagaon | I25: 3.75 | J25: 171696.71 | K25: 163043.32 | L25: 152988.32 | M25: 142582.92 | N25: 130425.52 | O25: 130425.52 | P25: 190435.58 | Q25: 190435.58 | R25: 190435.58 | S25: 190435.58 | T25: 183930.3 | U25: 178156.29 | W25: Dhusuma | X25: 177674.21 | Y25: 167420.65 | Z25: 155506.3 | AA25: 143176.75 | AB25: 128771.21 | AC25: 128771.21 | AD25: 199878.24 | AE25: 199878.24 | AF25: 199878.24 | AG25: 199878.24 | AH25: 192170.01 | AI25: 185328.28 | AJ25: 5825.9526 | AK25: 4699.1168 | AL25: 3389.7654 | AM25: 2034.785 | AN25: 451.66011 | AO25: 451.66011 | AP25: 8266.1075 | AQ25: 8266.1075 | AR25: 8266.1075 | AS25: 8266.1075 | AT25: 7418.9968 | AU25: 6667.1117 | AV25: 183500.17 | AW25: 172119.77 | AX25: 158896.06 | AY25: 145211.53 | AZ25: 129222.87 | BA25: 129222.87 | BB25: 208144.34 | BC25: 208144.34 | BD25: 208144.34 | BE25: 208144.34 | BF25: 199589.01 | BG25: 191995.39
A26: 24 | B26: 20.0148 | C26: 84.9656 | D26: Lakes/Ponds | E26: NA | F26: 3 | G26: 14540.93 | H26: Khubhiapalli | I26: 2.75 | J26: 34621.954 | K26: 32144.18 | L26: 29265.076 | M26: 26285.639 | N26: 22804.541 | O26: 22804.541 | P26: 39987.558 | Q26: 39987.558 | R26: 39987.558 | S26: 39987.558 | T26: 38124.864 | U26: 36471.561 | W26: Jaringi | X26: 183955.51 | Y26: 173265.07 | Z26: 160843.07 | AA26: 147988.19 | AB26: 132968.87 | AC26: 132968.87 | AD26: 207105.59 | AE26: 207105.59 | AF26: 207105.59 | AG26: 207105.59 | AH26: 199068.94 | AI26: 191935.7 | AJ26: 546.83216 | AK26: 302.2647 | AL26: 18.084213 | AM26: 0 | AN26: 0 | AO26: 0 | AP26: 1076.4413 | AQ26: 1076.4413 | AR26: 1076.4413 | AS26: 1076.4413 | AT26: 892.58508 | AU26: 729.39659 | AV26: 184502.34 | AW26: 173567.33 | AX26: 160861.15 | AY26: 147988.19 | AZ26: 132968.87 | BA26: 132968.87 | BB26: 208182.03 | BC26: 208182.03 | BD26: 208182.03 | BE26: 208182.03 | BF26: 199961.52 | BG26: 192665.1
A27: 25 | B27: 20.0075 | C27: 84.9658 | D27: Lakes/Ponds | E27: NA | F27: 2 | G27: 1837.4 | H27: Khubhiapalli | I27: 1.75 | J27: 2537.4494 | K27: 2224.3564 | L27: 1860.5512 | M27: 1484.068 | N27: 1044.1944 | O27: 1044.1944 | P27: 3215.45 | Q27: 3215.45 | R27: 3215.45 | S27: 3215.45 | T27: 2980.0791 | U27: 2771.1667 | W27: Kalyanpur | X27: 207633.85 | Y27: 194400.5 | Z27: 179023.71 | AA27: 163111.07 | AB27: 144519.14 | AC27: 144519.14 | AD27: 236290.59 | AE27: 236290.59 | AF27: 236290.59 | AG27: 236290.59 | AH27: 226342.27 | AI27: 217512.27 | AJ27: 0 | AK27: 0 | AL27: 0 | AM27: 0 | AN27: 0 | AO27: 0 | AP27: 395.03025 | AQ27: 395.03025 | AR27: 395.03025 | AS27: 395.03025 | AT27: 192.61675 | AU27: 12.956992 | AV27: 207633.85 | AW27: 194400.5 | AX27: 179023.71 | AY27: 163111.07 | AZ27: 144519.14 | BA27: 144519.14 | BB27: 236685.62 | BC27: 236685.62 | BD27: 236685.62 | BE27: 236685.62 | BF27: 226534.89 | BG27: 217525.23
A28: 26 | B28: 20.0069 | C28: 84.9659 | D28: Lakes/Ponds | E28: NA | F28: 3 | G28: 6228.45 | H28: Khubhiapalli | I28: 2.75 | J28: 14829.939 | K28: 13768.612 | L28: 12535.378 | M28: 11259.169 | N28: 9768.0781 | O28: 9768.0781 | P28: 17128.237 | Q28: 17128.237 | R28: 17128.237 | S28: 17128.237 | T28: 16330.373 | U28: 15622.198 | W28: Khubhiapalli | X28: 233624.48 | Y28: 218545.63 | Z28: 201024.44 | AA28: 182892.65 | AB28: 161707.93 | AC28: 161707.93 | AD28: 266277.62 | AE28: 266277.62 | AF28: 266277.62 | AG28: 266277.62 | AH28: 254941.94 | AI28: 244880.53 | AV28: 233624.48 | AW28: 218545.63 | AX28: 201024.44 | AY28: 182892.65 | AZ28: 161707.93 | BA28: 161707.93 | BB28: 266277.62 | BC28: 266277.62 | BD28: 266277.62 | BE28: 266277.62 | BF28: 254941.94 | BG28: 244880.53
A29: 27 | B29: 20.0063 | C29: 84.9665 | D29: Lakes/Ponds | E29: NA | F29: 2 | G29: 3637.72 | H29: Khubhiapalli | I29: 1.75 | J29: 5023.6913 | K29: 4403.8238 | L29: 3683.5553 | M29: 2938.1864 | N29: 2067.3163 | O29: 2067.3163 | P29: 6366.01 | Q29: 6366.01 | R29: 6366.01 | S29: 6366.01 | T29: 5900.0181 | U29: 5486.4093 | W29: Nandighora | X29: 776769.64 | Y29: 733995.16 | Z29: 684292.42 | AA29: 632857.61 | AB29: 572762.48 | AC29: 572762.48 | AD29: 869397.48 | AE29: 869397.48 | AF29: 869397.48 | AG29: 869397.48 | AH29: 837241.31 | AI29: 808699.89 | AV29: 776769.64 | AW29: 733995.16 | AX29: 684292.42 | AY29: 632857.61 | AZ29: 572762.48 | BA29: 572762.48 | BB29: 869397.48 | BC29: 869397.48 | BD29: 869397.48 | BE29: 869397.48 | BF29: 837241.31 | BG29: 808699.89
A30: 28 | B30: 20.0063 | C30: 84.9693 | D30: Lakes/Ponds | E30: NA | F30: 2 | G30: 721.48 | H30: Khubhiapalli | I30: 1.75 | J30: 996.36388 | K30: 873.42369 | L30: 730.57065 | M30: 582.7394 | N30: 410.01708 | O30: 410.01708 | P30: 1262.59 | Q30: 1262.59 | R30: 1262.59 | S30: 1262.59 | T30: 1170.1684 | U30: 1088.1361 | W30: Odagaon | X30: 183949.59 | Y30: 174049.03 | Z30: 162544.86 | AA30: 150639.79 | AB30: 136730.21 | AC30: 136730.21 | AD30: 205389.18 | AE30: 205389.18 | AF30: 205389.18 | AG30: 205389.18 | AH30: 197946.33 | AI30: 191340.15 | AJ30: 691.50497 | AK30: 495.14184 | AL30: 266.97341 | AM30: 155.35995 | AN30: 34.485162 | AO30: 34.485162 | AP30: 1335.2818 | AQ30: 1335.2818 | AR30: 1335.2818 | AS30: 1335.2818 | AT30: 1075.6767 | AU30: 845.25446 | AV30: 184641.09 | AW30: 174544.17 | AX30: 162811.84 | AY30: 150795.15 | AZ30: 136764.69 | BA30: 136764.69 | BB30: 206724.46 | BC30: 206724.46 | BD30: 206724.46 | BE30: 206724.46 | BF30: 199022 | BG30: 192185.4
A31: 29 | B31: 20.0049 | C31: 84.971 | D31: Lakes/Ponds | E31: NA | F31: 2 | G31: 549.59 | H31: Khubhiapalli | I31: 1.75 | J31: 758.98379 | K31: 665.33365 | L31: 556.51483 | M31: 443.90384 | N31: 312.332 | O31: 312.332 | P31: 961.7825 | Q31: 961.7825 | R31: 961.7825 | S31: 961.7825 | T31: 891.38002 | U31: 828.89164 | W31: Rabara | X31: 373476.82 | Y31: 351944.21 | Z31: 326923.92 | AA31: 301031.71 | AB31: 270779.91 | AC31: 270779.91 | AD31: 420105.54 | AE31: 420105.54 | AF31: 420105.54 | AG31: 420105.54 | AH31: 403918.17 | AI31: 389550.46 | AJ31: 496.32714 | AK31: 274.34776 | AL31: 16.413968 | AM31: 0 | AN31: 0 | AO31: 0 | AP31: 977.02193 | AQ31: 977.02193 | AR31: 977.02193 | AS31: 977.02193 | AT31: 810.14658 | AU31: 662.03006 | AV31: 373973.15 | AW31: 352218.56 | AX31: 326940.33 | AY31: 301031.71 | AZ31: 270779.91 | BA31: 270779.91 | BB31: 421082.56 | BC31: 421082.56 | BD31: 421082.56 | BE31: 421082.56 | BF31: 404728.32 | BG31: 390212.49
A32: 30 | B32: 19.9992 | C32: 84.9722 | D32: Lakes/Ponds | E32: NA | F32: 4 | G32: 8715.41 | H32: Khubhiapalli | I32: 3.75 | J32: 29466.801 | K32: 27981.695 | L32: 26256.044 | M32: 24470.257 | N32: 22383.788 | O32: 22383.788 | P32: 32682.787 | Q32: 32682.787 | R32: 32682.787 | S32: 32682.787 | T32: 31566.343 | U32: 30575.401 | W32: Saradapur | X32: 469067.88 | Y32: 440365.36 | Z32: 407013.85 | AA32: 372500.09 | AB32: 332175.07 | AC32: 332175.07 | AD32: 531222.97 | AE32: 531222.97 | AF32: 531222.97 | AG32: 531222.97 | AH32: 509645.55 | AI32: 490493.7 | AJ32: 120.76206 | AK32: 66.751944 | AL32: 3.9937061 | AM32: 0 | AN32: 0 | AO32: 0 | AP32: 237.7206 | AQ32: 237.7206 | AR32: 237.7206 | AS32: 237.7206 | AT32: 197.11792 | AU32: 161.07948 | AV32: 469188.64 | AW32: 440432.12 | AX32: 407017.84 | AY32: 372500.09 | AZ32: 332175.07 | BA32: 332175.07 | BB32: 531460.69 | BC32: 531460.69 | BD32: 531460.69 | BE32: 531460.69 | BF32: 509842.67 | BG32: 490654.78
A33: 31 | B33: 19.9964 | C33: 84.9729 | D33: Lakes/Ponds | E33: NA | F33: 4 | G33: 1121.71 | H33: Khubhiapalli | I33: 3.75 | J33: 3792.5015 | K33: 3601.3621 | L33: 3379.2635 | M33: 3149.4252 | N33: 2880.8878 | O33: 2880.8878 | P33: 4206.4125 | Q33: 4206.4125 | R33: 4206.4125 | S33: 4206.4125 | T33: 4062.7214 | U33: 3935.183 | W33: Sikharpur | X33: 267119.45 | Y33: 249586.95 | Z33: 229214.68 | AA33: 208132.46 | AB33: 183500.53 | AC33: 183500.53 | AD33: 305085.96 | AE33: 305085.96 | AF33: 305085.96 | AG33: 305085.96 | AH33: 291905.72 | AI33: 280207.1 | AV33: 267119.45 | AW33: 249586.95 | AX33: 229214.68 | AY33: 208132.46 | AZ33: 183500.53 | BA33: 183500.53 | BB33: 305085.96 | BC33: 305085.96 | BD33: 305085.96 | BE33: 305085.96 | BF33: 291905.72 | BG33: 280207.1
A34: 32 | B34: 19.992 | C34: 84.9736 | D34: Lakes/Ponds | E34: NA | F34: 3 | G34: 2199.67 | H34: Khubhiapalli | I34: 2.75 | J34: 5237.4143 | K34: 4862.5905 | L34: 4427.0558 | M34: 3976.3435 | N34: 3449.7425 | O34: 3449.7425 | P34: 6049.0925 | Q34: 6049.0925 | R34: 6049.0925 | S34: 6049.0925 | T34: 5767.3148 | U34: 5517.2123 | W34: Grand Total | X34: 3622916.8 | Y34: 3401980.4 | Z34: 3145258.6 | AA34: 2879590.3 | AB34: 2569190.3 | AC34: 2569190.3 | AD34: 4101353 | AE34: 4101353 | AF34: 4101353 | AG34: 4101353 | AH34: 3935261.7 | AI34: 3787841.2 | AJ34: 7681.3789 | AK34: 5837.623 | AL34: 3695.2307 | AM34: 2190.145 | AN34: 486.14528 | AO34: 486.14528 | AP34: 12290.426 | AQ34: 12290.426 | AR34: 12290.426 | AS34: 12290.426 | AT34: 10587.14 | AU34: 9077.8292 | AV34: 3630598.2 | AW34: 3407818 | AX34: 3148953.8 | AY34: 2881780.5 | AZ34: 2569676.4 | BA34: 2569676.4 | BB34: 4113643.4 | BC34: 4113643.4 | BD34: 4113643.4 | BE34: 4113643.4 | BF34: 3945848.9 | BG34: 3796919
A35: 33 | B35: 19.9926 | C35: 84.9731 | D35: Lakes/Ponds | E35: NA | F35: 3 | G35: 877.95 | H35: Khubhiapalli | I35: 2.75 | J35: 2090.399 | K35: 1940.7963 | L35: 1766.9622 | M35: 1587.0702 | N35: 1376.889 | O35: 1376.889 | P35: 2414.3625 | Q35: 2414.3625 | R35: 2414.3625 | S35: 2414.3625 | T35: 2301.8971 | U35: 2202.0742
A36: 34 | B36: 20.0106 | C36: 84.9703 | D36: Lakes/Ponds | E36: NA | F36: 2 | G36: 1969.51 | H36: Khubhiapalli | I36: 1.75 | J36: 2719.8933 | K36: 2384.2888 | L36: 1994.3258 | M36: 1590.7732 | N36: 1119.2725 | O36: 1119.2725 | P36: 3446.6425 | Q36: 3446.6425 | R36: 3446.6425 | S36: 3446.6425 | T36: 3194.3483 | U36: 2970.415
A37: 35 | B37: 20.0087 | C37: 84.9736 | D37: Lakes/Ponds | E37: NA | F37: 2 | G37: 1962.42 | H37: Odagaon | I37: 1.75 | J37: 2710.102 | K37: 2375.7057 | L37: 1987.1465 | M37: 1585.0466 | N37: 1115.2433 | O37: 1115.2433 | P37: 3434.235 | Q37: 3434.235 | R37: 3434.235 | S37: 3434.235 | T37: 3182.849 | U37: 2959.7218
A38: 36 | B38: 20.0116 | C38: 84.9759 | D38: Lakes/Ponds | E38: NA | F38: 3 | G38: 2145.28 | H38: Odagaon | I38: 2.75 | J38: 5107.9117 | K38: 4742.356 | L38: 4317.5905 | M38: 3878.0227 | N38: 3364.4426 | O38: 3364.4426 | P38: 5899.52 | Q38: 5899.52 | R38: 5899.52 | S38: 5899.52 | T38: 5624.7096 | U38: 5380.7913
A39: 37 | B39: 20.0103 | C39: 84.9755 | D39: Lakes/Ponds | E39: NA | F39: 2 | G39: 757.34 | H39: Odagaon | I39: 1.75 | J39: 1045.8865 | K39: 916.8358 | L39: 766.88248 | M39: 611.70352 | N39: 430.39632 | O39: 430.39632 | P39: 1325.345 | Q39: 1325.345 | R39: 1325.345 | S39: 1325.345 | T39: 1228.3297 | U39: 1142.2202
A40: 38 | B40: 20.0193 | C40: 84.9732 | D40: Lakes/Ponds | E40: NA | F40: 3 | G40: 5322.6 | H40: Khubhiapalli | I40: 2.75 | J40: 12673.111 | K40: 11766.14 | L40: 10712.265 | M40: 9621.664 | N40: 8347.4336 | O40: 8347.4336 | P40: 14637.15 | Q40: 14637.15 | R40: 14637.15 | S40: 14637.15 | T40: 13955.325 | U40: 13350.145
...

Sheet Daspalla
A1: Descrip | B1: Depth | C1: Area_m2 | D1: Kharif_str | E1: Rabi_loss | F1: Rabi_str | G1: Rabi_strg | H1: Summer_str | I1: Total_strg
A2: Lakes/Ponds | B2: 2 | C2: 317.354 | D2: 634.71 | E2: =$J$2/1000*C2 -> 171.18075 | F2: =D2-E2 -> 463.52925 | G2: 317.354 | H2: 158.677 | I2: 1110.74 | J2: 539.4 | K2: 642.3
A3: Lakes/Ponds | B3: 2 | C3: 340.002 | D3: 680 | E3: =$J$2/1000*C3 -> 183.39708 | F3: =D3-E3 -> 496.60292 | G3: 340.002 | H3: 170.001 | I3: 1190
A4: Lakes/Ponds | B4: 2 | C4: 330.181 | D4: 660.36 | E4: =$J$2/1000*C4 -> 178.09963 | F4: =D4-E4 -> 482.26037 | G4: 330.181 | H4: 165.091 | I4: 1155.63
A5: Lakes/Ponds | B5: 2 | C5: 406.122 | D5: 812.24 | E5: =$J$2/1000*C5 -> 219.06221 | F5: =D5-E5 -> 593.17779 | G5: 406.122 | H5: 203.061 | I5: 1421.42
A6: Lakes/Ponds | B6: 3 | C6: 3052.328 | D6: 9156.98 | E6: =$J$2/1000*C6 -> 1646.4257 | F6: =D6-E6 -> 7510.5543 | G6: 4578.492 | H6: 2289.246 | I6: 16024.72
A7: Lakes/Ponds | B7: 3 | C7: 2333.824 | D7: 7001.47 | E7: =$J$2/1000*C7 -> 1258.8647 | F7: =D7-E7 -> 5742.6053 | G7: 3500.736 | H7: 1750.368 | I7: 12252.57
A8: Lakes/Ponds | B8: 3 | C8: 1814.679 | D8: 5444.04 | E8: =$J$2/1000*C8 -> 978.83785 | F8: =D8-E8 -> 4465.2021 | G8: 2722.019 | H8: 1361.009 | I8: 9527.07
A9: Lakes/Ponds | B9: 3 | C9: 2210.277 | D9: 6630.83 | E9: =$J$2/1000*C9 -> 1192.2234 | F9: =D9-E9 -> 5438.6066 | G9: 3315.416 | H9: 1657.708 | I9: 11603.95
A10: Lakes/Ponds | B10: 2.5 | C10: 919.38 | D10: 2298.45 | E10: =$J$2/1000*C10 -> 495.91357 | F10: =D10-E10 -> 1802.5364 | G10: 1149.225 | H10: 574.613 | I10: 4022.29
A11: Lakes/Ponds | B11: 2.5 | C11: 860.881 | D11: 2152.2 | E11: =$J$2/1000*C11 -> 464.35921 | F11: =D11-E11 -> 1687.8408 | G11: 1076.101 | H11: 538.051 | I11: 3766.35
A12: Lakes/Ponds | B12: 4 | C12: 4300.193 | D12: 17200.77 | E12: =$J$2/1000*C12 -> 2319.5241 | F12: =D12-E12 -> 14881.246 | G12: 8600.386 | H12: 4300.193 | I12: 30101.35
A13: Lakes/Ponds | B13: 2 | C13: 416.878 | D13: 833.76 | E13: =$J$2/1000*C13 -> 224.86399 | F13: =D13-E13 -> 608.89601 | G13: 416.878 | H13: 208.439 | I13: 1459.08
A14: Lakes/Ponds | B14: 2 | C14: 566.224 | D14: 1132.45 | E14: =$J$2/1000*C14 -> 305.42123 | F14: =D14-E14 -> 827.02877 | G14: 566.224 | H14: 283.112 | I14: 1981.79
... A156: Lakes/Ponds | B156: 4 | C156: 3704.702 | D156: 14818.81 | E156: =$J$2/1000*C156 -> 1998.3163 | F156: =D156-E156 -> 12820.494 | G156: 7409.404 | H156: 3704.702 | I156: 25932.92
A157: Total | B157: =AVERAGE(B2:B156) -> 2.6483871 | C157: =SUM(C2:C156) -> 297838.91 | D157: =SUM(D2:D156) -> 904692.13 | G157: =SUM(G2:G156) -> 452346.12 | H157: =SUM(H2:H156) -> 226173.08 | I157: =SUM(I2:I156) -> 1583211.3

Sheet Daspalla_22
A1: FID | B1: Latitude | C1: Longitude | D1: descriptio | E1: Depth_m | F1: Depth_m (after deducting safe factor) | G1: Area_m2 | H1: Storage (m3) | T1: MWS_Name
H2: Jan | I2: Feb | J2: Mar | K2: Apr | L2: May | M2: Jun | N2: Jul | O2: Aug | P2: Sep | Q2: Oct | R2: Nov | S2: Dec | W2: Month | X2: Season | Y2: Evaporation (mm/day) | Z2: Deep percolation (mm/day) | AA2: Total (mm/day) | AB2: Total (mm/month) | AC2: Total Depth (m/month)
A3: 0 | B3: 20.3248 | C3: 84.478 | D3: Lakes/Ponds | E3: 2 | F3: =E3-$Z$21 -> 1.75 | G3: 317.354 | H3: =IF(S3-$AC$3<0, 0, S3-$AC$3) -> 1.381 | I3: =IF(H3-$AC$4<0, 0, H3-$AC$4) -> 1.2106 | J3: =IF(I3-$AC$5<0, 0, I3-$AC$5) -> 1.0126 | K3: =IF(J3-$AC$6<0, 0, J3-$AC$6) -> 0.8077 | L3: =IF(K3-$AC$7<0, 0, K3-$AC$7) -> 0.5683 | M3: =F3 -> 1.75 | N3: =F3 -> 1.75 | O3: =F3 -> 1.75 | P3: =F3 -> 1.75 | Q3: =F3 -> 1.75 | R3: =IF(Q3-$AC$13<0, 0, Q3-$AC$13) -> 1.6219 | S3: =IF(R3-$AC$14<0, 0, R3-$AC$14) -> 1.5082 | T3: Gunduribadi | W3: Jan | X3: Rabi | Y3: 2.24 | Z3: 2 | AA3: =Y3+Z3 -> 4.24 | AB3: =AA3*30 -> 127.2 | AC3: =AB3/1000 -> 0.1272
A4: 1 | B4: 20.3297 | C4: 84.4857 | D4: Lakes/Ponds | E4: 2 | F4: =E4-$Z$21 -> 1.75 | G4: 340.002 | H4: =IF(S4-$AC$3<0, 0, S4-$AC$3) -> 1.381 | I4: =IF(H4-$AC$4<0, 0, H4-$AC$4) -> 1.2106 | J4: =IF(I4-$AC$5<0, 0, I4-$AC$5) -> 1.0126 | K4: =IF(J4-$AC$6<0, 0, J4-$AC$6) -> 0.8077 | L4: =IF(K4-$AC$7<0, 0, K4-$AC$7) -> 0.5683 | M4: =F4 -> 1.75 | N4: =F4 -> 1.75 | O4: =F4 -> 1.75 | P4: =F4 -> 1.75 | Q4: =F4 -> 1.75 | R4: =IF(Q4-$AC$13<0, 0, Q4-$AC$13) -> 1.6219 | S4: =IF(R4-$AC$14<0, 0, R4-$AC$14) -> 1.5082 | T4: Gunduribadi | W4: Feb | X4: Rabi | Y4: 3.68 | Z4: 2 | AA4: =Y4+Z4 -> 5.68 | AB4: =AA4*30 -> 170.4 | AC4: =AB4/1000 -> 0.1704
A5: 2 | B5: 20.3296 | C5: 84.4841 | D5: Lakes/Ponds | E5: 2 | F5: =E5-$Z$21 -> 1.75 | G5: 330.181 | H5: =IF(S5-$AC$3<0, 0, S5-$AC$3) -> 1.381 | I5: =IF(H5-$AC$4<0, 0, H5-$AC$4) -> 1.2106 | J5: =IF(I5-$AC$5<0, 0, I5-$AC$5) -> 1.0126 | K5: =IF(J5-$AC$6<0, 0, J5-$AC$6) -> 0.8077 | L5: =IF(K5-$AC$7<0, 0, K5-$AC$7) -> 0.5683 | M5: =F5 -> 1.75 | N5: =F5 -> 1.75 | O5: =F5 -> 1.75 | P5: =F5 -> 1.75 | Q5: =F5 -> 1.75 | R5: =IF(Q5-$AC$13<0, 0, Q5-$AC$13) -> 1.6219 | S5: =IF(R5-$AC$14<0, 0, R5-$AC$14) -> 1.5082 | T5: Gunduribadi | W5: Mar | X5: Summer | Y5: 4.6 | Z5: 2 | AA5: =Y5+Z5 -> 6.6 | AB5: =AA5*30 -> 198 | AC5: =AB5/1000 -> 0.198
A6: 3 | B6: 20.3297 | C6: 84.4833 | D6: Lakes/Ponds | E6: 2 | F6: =E6-$Z$21 -> 1.75 | G6: 406.122 | H6: =IF(S6-$AC$3<0, 0, S6-$AC$3) -> 1.381 | I6: =IF(H6-$AC$4<0, 0, H6-$AC$4) -> 1.2106 | J6: =IF(I6-$AC$5<0, 0, I6-$AC$5) -> 1.0126 | K6: =IF(J6-$AC$6<0, 0, J6-$AC$6) -> 0.8077 | L6: =IF(K6-$AC$7<0, 0, K6-$AC$7) -> 0.5683 | M6: =F6 -> 1.75 | N6: =F6 -> 1.75 | O6: =F6 -> 1.75 | P6: =F6 -> 1.75 | Q6: =F6 -> 1.75 | R6: =IF(Q6-$AC$13<0, 0, Q6-$AC$13) -> 1.6219 | S6: =IF(R6-$AC$14<0, 0, R6-$AC$14) -> 1.5082 | T6: Gunduribadi | W6: Apr | X6: Summer | Y6: 4.83 | Z6: 2 | AA6: =Y6+Z6 -> 6.83 | AB6: =AA6*30 -> 204.9 | AC6: =AB6/1000 -> 0.2049
A7: 4 | B7: 20.3331 | C7: 84.4887 | D7: Lakes/Ponds | E7: 3 | F7: =E7-$Z$21 -> 2.75 | G7: 3052.328 | H7: =IF(S7-$AC$3<0, 0, S7-$AC$3) -> 2.381 | I7: =IF(H7-$AC$4<0, 0, H7-$AC$4) -> 2.2106 | J7: =IF(I7-$AC$5<0, 0, I7-$AC$5) -> 2.0126 | K7: =IF(J7-$AC$6<0, 0, J7-$AC$6) -> 1.8077 | L7: =IF(K7-$AC$7<0, 0, K7-$AC$7) -> 1.5683 | M7: =F7 -> 2.75 | N7: =F7 -> 2.75 | O7: =F7 -> 2.75 | P7: =F7 -> 2.75 | Q7: =F7 -> 2.75 | R7: =IF(Q7-$AC$13<0, 0, Q7-$AC$13) -> 2.6219 | S7: =IF(R7-$AC$14<0, 0, R7-$AC$14) -> 2.5082 | T7: Gunduribadi | W7: May | X7: Summer | Y7: 5.98 | Z7: 2 | AA7: =Y7+Z7 -> 7.98 | AB7: =AA7*30 -> 239.4 | AC7: =AB7/1000 -> 0.2394
A8: 5 | B8: 20.3328 | C8: 84.4876 | D8: Lakes/Ponds | E8: 3 | F8: =E8-$Z$21 -> 2.75 | G8: 2333.824 | H8: =IF(S8-$AC$3<0, 0, S8-$AC$3) -> 2.381 | I8: =IF(H8-$AC$4<0, 0, H8-$AC$4) -> 2.2106 | J8: =IF(I8-$AC$5<0, 0, I8-$AC$5) -> 2.0126 | K8: =IF(J8-$AC$6<0, 0, J8-$AC$6) -> 1.8077 | L8: =IF(K8-$AC$7<0, 0, K8-$AC$7) -> 1.5683 | M8: =F8 -> 2.75 | N8: =F8 -> 2.75 | O8: =F8 -> 2.75 | P8: =F8 -> 2.75 | Q8: =F8 -> 2.75 | R8: =IF(Q8-$AC$13<0, 0, Q8-$AC$13) -> 2.6219 | S8: =IF(R8-$AC$14<0, 0, R8-$AC$14) -> 2.5082 | T8: Gunduribadi | W8: Jun | X8: Kharif
A9: 6 | B9: 20.3336 | C9: 84.4841 | D9: Lakes/Ponds | E9: 3 | F9: =E9-$Z$21 -> 2.75 | G9: 1814.679 | H9: =IF(S9-$AC$3<0, 0, S9-$AC$3) -> 2.381 | I9: =IF(H9-$AC$4<0, 0, H9-$AC$4) -> 2.2106 | J9: =IF(I9-$AC$5<0, 0, I9-$AC$5) -> 2.0126 | K9: =IF(J9-$AC$6<0, 0, J9-$AC$6) -> 1.8077 | L9: =IF(K9-$AC$7<0, 0, K9-$AC$7) -> 1.5683 | M9: =F9 -> 2.75 | N9: =F9 -> 2.75 | O9: =F9 -> 2.75 | P9: =F9 -> 2.75 | Q9: =F9 -> 2.75 | R9: =IF(Q9-$AC$13<0, 0, Q9-$AC$13) -> 2.6219 | S9: =IF(R9-$AC$14<0, 0, R9-$AC$14) -> 2.5082 | T9: Gunduribadi | W9: Jul | X9: Kharif
